#Try and Except
#x is not defiend so the except will run
try:
  print(x)
except:
  print("An exception occurred")